<?xml version="1.0" encoding="utf-8"?>
<!-- =================================================================================== -->
<!-- |    This document was autogenerated by xacro from robotino_sim.urdf.xacro        | -->
<!-- |    EDITING THIS FILE BY HAND IS NOT RECOMMENDED                                 | -->
<!-- =================================================================================== -->
<robot name="robotino">
  <!-- 20 -->
  <!-- Space btw top of beam and the each joint -->
  <!-- Space btw top of beam and the each joint -->

  <link name="base_link">
    <inertial>
      <mass value="0.5"/>
      <origin xyz="0 0 0.05"/>
      <inertia ixx="0.8750" ixy="0.0" ixz="0.0" iyy="0.875" iyz="0.0" izz="1"/>
    </inertial>
    <visual>
      <origin rpy="0 0 1.570795" xyz="0.01 0 0"/>
      <geometry>
        <mesh filename="package://robotino_description/meshes/parts/robotino_base.dae" scale="0.01 0.01 0.01"/>
      </geometry>
    </visual>

     <collision>
      <geometry>
        <box size="0 0 0"/>
      </geometry>
    </collision>
  </link>
  

  <link name="wheel0_link">
    <inertial>
      <mass value="2"/>
      <origin rpy="0 0 0" xyz="0 0 0"/>
      <inertia ixx="0.04" ixy="0.0" ixz="0.0" iyy="0.04" iyz="0.0" izz="0.04"/>
    </inertial>
    <visual>
      <origin rpy="0 0 0" xyz="0 0 0"/>
      <geometry>
        <mesh filename="package://robotino_description/meshes/parts/robotino_wheel.dae" scale="0.01 0.01 0.01"/>
      </geometry>
    </visual>
  </link>
  
  <joint name="wheel0_joint" type="continuous">
    <origin rpy="0 0 1.04719666667" xyz="0.065 0.11 0.04"/>
    <axis xyz="-1 0 0"/>
    <parent link="base_link"/>
    <child link="wheel0_link"/>
  </joint>
  <link name="wheel1_link">
    <inertial>
      <mass value="2"/>
      <origin rpy="0 0 0" xyz="0 0 0"/>
      <inertia ixx="0.04" ixy="0.0" ixz="0.0" iyy="0.04" iyz="0.0" izz="0.04"/>
    </inertial>
    <visual>
      <origin rpy="0 0 0" xyz="0 0 0"/>
      <geometry>
        <mesh filename="package://robotino_description/meshes/parts/robotino_wheel.dae" scale="0.01 0.01 0.01"/>
      </geometry>
    </visual>
  </link>
  <joint name="wheel1_joint" type="continuous">
    <origin rpy="0 0 3.14159" xyz="-0.13 0 0.04"/>
    <axis xyz="1 0 0"/>
    <parent link="base_link"/>
    <child link="wheel1_link"/>
  </joint>
  <link name="wheel2_link">
    <inertial>
      <mass value="2"/>
      <origin rpy="0 0 0" xyz="0 0 0"/>
      <inertia ixx="0.04" ixy="0.0" ixz="0.0" iyy="0.04" iyz="0.0" izz="0.04"/>
    </inertial>
    <visual>
      <origin rpy="0 0 0" xyz="0 0 0"/>
      <geometry>
        <mesh filename="package://robotino_description/meshes/parts/robotino_wheel.dae" scale="0.01 0.01 0.01"/>
      </geometry>
    </visual>
  </link>
  <joint name="wheel2_joint" type="continuous">
    <origin rpy="0 0 -1.04719666667" xyz="0.065 -0.11 0.04"/>
    <axis xyz="-1 0 0"/>
    <parent link="base_link"/>
    <child link="wheel2_link"/>
  </joint>

  <link name="lasersensor_link">
    <inertial>
      <origin rpy="0 0 0" xyz="-0.00056497 7.11770000114844E-09 0.018756"/>
      <mass value="0.015915"/>
      <inertia ixx="7.2795244626149E-05" ixy="8.59363271873857E-12" ixz="-1.00192037963258E-06" iyy="7.06968247556297E-05" iyz="-1.1608849365102E-11" izz="0.000102602650447107"/>
    </inertial>
    <visual>
      <origin rpy="1.5707963267949 0 0" xyz="0 0 -0.018756"/>
      <geometry>
        <mesh filename="package://robotino_description/lidar/meshes/lidar.STL"/>
      </geometry>
      <material name="">
        <color rgba="0.64314 0.61569 0.6 1"/>
      </material>
    </visual>
  </link>

  <joint name="lasersensor_joint" type="fixed">
    <origin rpy="0 0 0" xyz="0.0 0 0.26"/>
    <parent link="yaw_link"/>
    <child link="lasersensor_link"/>
  </joint>

  <link name="pantiltring_link">
    <inertial>
      <origin rpy="0 0 0" xyz="4.0968E-16 -0.015 9.18454765366783E-19"/>
      <mass value="0.094154"/>
      <inertia ixx="0.001312241311471" ixy="-6.9590790831882E-33" ixz="-1.3339474659106E-34" iyy="0.00261035959316777" iyz="-7.94841947889434E-20" izz="0.00131224131147099"/>
    </inertial>
    <visual>
      <origin rpy="0 0 0" xyz="0 0 0"/>
      <geometry>
        <mesh filename="package://robotino_description/ring/meshes/ring.STL"/>
      </geometry>
      <material name="">
        <color rgba="0.79216 0.81961 0.93333 1"/>
      </material>
    </visual>
  </link>
  <joint name="pantiltring_joint" type="fixed">
    <origin rpy="0 0 0" xyz="0.0 0 0.173"/>
    <parent link="yaw_link"/>
    <child link="pantiltring_link"/>
  </joint>

  <link name="pantilt_link">
    <inertial>
      <origin rpy="0 0 0" xyz="-0.00076068 0.053384 -0.00086946"/>
      <mass value="0.17709"/>
      <inertia ixx="0.022066" ixy="0.00017957" ixz="-1.0212E-05" iyy="0.016545" iyz="0.00019743" izz="0.022127"/>
    </inertial>
    <visual>
      <origin rpy="0 0 0" xyz="0 0 0"/>
      <geometry>
        <mesh filename="package://robotino_description/pantiltholder/meshes/camerabase_Link.STL"/>
      </geometry>
      <material name="">
        <color rgba="0.79216 0.81961 0.93333 1"/>
      </material>
    </visual>
  </link>

  <joint name="pantilt_joint" type="fixed">
    <origin rpy="0 0 0" xyz="0.0 0 0.157"/>
    <parent link="pantiltring_link"/>
    <child link="pantilt_link"/>
  </joint>

  <link name="cameraholder_link">
    <inertial>
      <origin rpy="0 0 0" xyz="0.08119 -9.6149E-11 -0.006335"/>
      <mass value="0.061321"/>
      <inertia ixx="1.6538E-06" ixy="1.156E-14" ixz="1.0178E-05" iyy="7.7966E-05" iyz="-6.9072E-14" izz="7.6312E-05"/>
    </inertial>
    <visual>
      <origin rpy="0 0 0" xyz="0 0 -0.32"/>
      <geometry>
        <mesh filename="package://robotino_description/pantiltholder/meshes/cameraholder_Link.STL"/>
      </geometry>
      <material name="">
        <color rgba="0.79216 0.81961 0.93333 1"/>
      </material>
    </visual>
  </link>
  <joint name="cameraholder_joint" type="continuous">
    <origin rpy="0 0 0" xyz="0.0 0 0.32"/>
    <origin rpy="0.050256 -1.5708 0" xyz="0 0 0"/>
    <parent link="pantilt_link"/>
    <child link="cameraholder_link"/>
    <axis xyz="0 0 1"/>
  </joint>
  <transmission name="cameraholder_joint_trans">
    <type>transmission_interface/SimpleTransmission</type>
    <joint name="cameraholder_joint">
      <hardwareInterface>hardware_interface/PositionJointInterface</hardwareInterface>
    </joint>
    <actuator name="cameraholder_motor">
      <hardwareInterface>hardware_interface/PositionJointInterface</hardwareInterface>
      <mechanicalReducation>1</mechanicalReducation>
    </actuator>
  </transmission>
  <link name="imu_link">
    <visual>
      <origin rpy="0 0 0" xyz="0 0 0"/>
      <geometry>
        <box size="0.018 0.016 0.007"/>
      </geometry>
      <material name="xsens-orange"/>
    </visual>
    <inertial>
      <mass value="0"/>
      <origin xyz="0 0 0"/>
      <inertia ixx="1.60333333333e-05" ixy="0.0" ixz="0.0" iyy="2.80333333333e-05" iyz="0.0" izz="1.60333333333e-05"/>
    </inertial>
  </link>
  <joint name="cameraholder_link_to_imu_link" type="fixed">
    <parent link="cameraholder_link"/>
    <child link="imu_link"/>
    <origin rpy="0 0 0" xyz="0 0 0"/>
  </joint>

</robot>