<?xml version="1.0" ?>
<!-- =================================================================================== -->
<!-- |    This document was autogenerated by xacro from robotino.urdf.xacro            | -->
<!-- |    EDITING THIS FILE BY HAND IS NOT RECOMMENDED                                 | -->
<!-- =================================================================================== -->
<robot name="robotino" xmlns:xacro="http://wiki.ros.org/xacro">
  <link name="base_link">
    <inertial>
      <mass value="20"/>
      <origin xyz="0 0 0"/>
      <inertia ixx="1.0" ixy="0.0" ixz="0.0" iyy="1.0" iyz="0.0" izz="1.0"/>
    </inertial>
    <visual>
      <origin rpy="0 0 1.570795" xyz="0.01 0 0"/>
      <geometry>
        <mesh filename="package://robotino_description/meshes/parts/robotino_base.dae" scale="0.01 0.01 0.01"/>
      </geometry>
    </visual>
    <collision>
      <origin rpy="0 0 0" xyz="0 0 0.025"/>
      <geometry>
        <cylinder length="0.05" radius="0.18"/>
      </geometry>
    </collision>
  </link>
  <gazebo reference="base_link">
    <material>Gazebo/White</material>
    <turnGravityOff>false</turnGravityOff>
  </gazebo>
  <link name="wheel0_link">
    <inertial>
      <mass value="0.00001"/>
      <origin xyz="0 0 0"/>
      <inertia ixx="1.0" ixy="0.0" ixz="0.0" iyy="1.0" iyz="0.0" izz="1.0"/>
    </inertial>
    <visual>
      <origin rpy="0 0 0" xyz="0 0 0"/>
      <geometry>
        <mesh filename="package://robotino_description/meshes/parts/robotino_wheel.dae" scale="0.01 0.01 0.01"/>
      </geometry>
    </visual>
  </link>
  <gazebo reference="wheel0_link">
    <material>Gazebo/Yellow</material>
    <turnGravityOff>false</turnGravityOff>
  </gazebo>
  <joint name="wheel0_joint" type="continuous">
    <origin rpy="0 0 1.04719666667" xyz="0.065 0.11 0.04"/>
    <axis xyz="-1 0 0"/>
    <parent link="base_link"/>
    <child link="wheel0_link"/>
  </joint>
  <transmission name="wheel0_joint_trans">
    <type>transmissio_interface/SimpleTransmission</type>
    <joint name="wheel0_joint"/>
    <actuator name="wheel0_motor">
      <hardwareInterface>EffortJointInterface</hardwareInterface>
      <mechanicalReducation>1</mechanicalReducation>
    </actuator>
  </transmission>
  <link name="wheel1_link">
    <inertial>
      <mass value="0.00001"/>
      <origin xyz="0 0 0"/>
      <inertia ixx="1.0" ixy="0.0" ixz="0.0" iyy="1.0" iyz="0.0" izz="1.0"/>
    </inertial>
    <visual>
      <origin rpy="0 0 0" xyz="0 0 0"/>
      <geometry>
        <mesh filename="package://robotino_description/meshes/parts/robotino_wheel.dae" scale="0.01 0.01 0.01"/>
      </geometry>
    </visual>
  </link>
  <gazebo reference="wheel1_link">
    <material>Gazebo/Yellow</material>
    <turnGravityOff>false</turnGravityOff>
  </gazebo>
  <joint name="wheel1_joint" type="continuous">
    <origin rpy="0 0 0" xyz="-0.13 0 0.04"/>
    <axis xyz="1 0 0"/>
    <parent link="base_link"/>
    <child link="wheel1_link"/>
  </joint>
  <transmission name="wheel1_joint_trans">
    <type>transmissio_interface/SimpleTransmission</type>
    <joint name="wheel1_joint"/>
    <actuator name="wheel1_motor">
      <hardwareInterface>EffortJointInterface</hardwareInterface>
      <mechanicalReducation>1</mechanicalReducation>
    </actuator>
  </transmission>
  <link name="wheel2_link">
    <inertial>
      <mass value="0.00001"/>
      <origin xyz="0 0 0"/>
      <inertia ixx="1.0" ixy="0.0" ixz="0.0" iyy="1.0" iyz="0.0" izz="1.0"/>
    </inertial>
    <visual>
      <origin rpy="0 0 0" xyz="0 0 0"/>
      <geometry>
        <mesh filename="package://robotino_description/meshes/parts/robotino_wheel.dae" scale="0.01 0.01 0.01"/>
      </geometry>
    </visual>
  </link>
  <gazebo reference="wheel2_link">
    <material>Gazebo/Yellow</material>
    <turnGravityOff>false</turnGravityOff>
  </gazebo>
  <joint name="wheel2_joint" type="continuous">
    <origin rpy="0 0 -1.04719666667" xyz="0.065 -0.11 0.04"/>
    <axis xyz="-1 0 0"/>
    <parent link="base_link"/>
    <child link="wheel2_link"/>
  </joint>
  <transmission name="wheel2_joint_trans">
    <type>transmissio_interface/SimpleTransmission</type>
    <joint name="wheel2_joint"/>
    <actuator name="wheel2_motor">
      <hardwareInterface>EffortJointInterface</hardwareInterface>
      <mechanicalReducation>1</mechanicalReducation>
    </actuator>
  </transmission>
  <link name="command_bridge_link">
    <inertial>
      <mass value="0.00001"/>
      <origin xyz="0 0 0"/>
      <inertia ixx="1.0" ixy="0.0" ixz="0.0" iyy="1.0" iyz="0.0" izz="1.0"/>
    </inertial>
    <collision>
      <origin rpy="0 0 0" xyz="0 0 0"/>
      <geometry>
        <box size="0.25 0.11 0.16"/>
      </geometry>
    </collision>
  </link>
  <joint name="command_bridge_joint" type="fixed">
    <origin rpy="0 0 1.570795" xyz="-0.05 0 0.13"/>
    <parent link="base_link"/>
    <child link="command_bridge_link"/>
  </joint>
  <link name="anglebracketusb_link">
    <inertial>
      <mass value="0.00001"/>
      <origin xyz="0 0 0"/>
      <inertia ixx="1.0" ixy="0.0" ixz="0.0" iyy="1.0" iyz="0.0" izz="1.0"/>
    </inertial>
    <visual>
      <origin rpy="0 0 0" xyz="0 0 0"/>
      <geometry>
        <mesh filename="package://robotino_description/meshes/parts/angle_bracket_usb_hub.dae" scale="0.01 0.01 0.01"/>
      </geometry>
    </visual>
  </link>
  <joint name="anglebracketusb_joint" type="fixed">
    <origin rpy="0 0 1.570795" xyz="0.008 0 0.137"/>
    <parent link="base_link"/>
    <child link="anglebracketusb_link"/>
  </joint>
  <gazebo>
    <plugin filename="libgazebo_ros_planar_move.so" name="object_controller">
      <commandTopic>cmd_vel</commandTopic>
      <odometryTopic>odom</odometryTopic>
      <odometryFrame>odom</odometryFrame>
      <odometryRate>20</odometryRate>
      <robotBaseFrame>base_link</robotBaseFrame>
    </plugin>
    <plugin filename="libgazebo_ros_control.so" name="gazebo_ros_control"/>
  </gazebo>
</robot>
